<robot
	name="edwin">
	<link
		name="base_link">
		<inertial>
			<origin
				xyz="-3.7358E-35 -2.529E-18 0.0088139"
				rpy="0 0 0" />
			<mass
				value="1.1856" />
			<inertia
				ixx="0.0059712"
				ixy="4.603E-36"
				ixz="3.0666E-36"
				iyy="0.0059712"
				iyz="-3.325E-19"
				izz="0.011871" />
		</inertial>
		<visual>
			<origin
				xyz="0 0 0"
				rpy="0 0 0" />
			<geometry>
				<mesh
					filename="package://edwin_description/meshes/base_link.STL" />
			</geometry>
			<material
				name="">
				<color
					rgba="0.79216 0.81961 0.93333 1" />
			</material>
		</visual>
		<collision>
			<origin
				xyz="0 0 0"
				rpy="0 0 0" />
			<geometry>
				<mesh
					filename="package://edwin_description/meshes/base_link.STL" />
			</geometry>
		</collision>
	</link>
	<link
		name="link_1">
		<inertial>
			<origin
				xyz="-0.018367 -0.0077664 0.069822"
				rpy="0 0 0" />
			<mass
				value="4.8214" />
			<inertia
				ixx="0.044516"
				ixy="-0.00066637"
				ixz="0.0028019"
				iyy="0.04368"
				iyz="-0.0055911"
				izz="0.03291" />
		</inertial>
		<visual>
			<origin
				xyz="0 0 0"
				rpy="0 0 0" />
			<geometry>
				<mesh
					filename="package://edwin_description/meshes/link_1.STL" />
			</geometry>
			<material
				name="">
				<color
					rgba="0.79216 0.81961 0.93333 1" />
			</material>
		</visual>
		<collision>
			<origin
				xyz="0 0 0"
				rpy="0 0 0" />
			<geometry>
				<mesh
					filename="package://edwin_description/meshes/link_1.STL" />
			</geometry>
		</collision>
	</link>
	<joint
		name="waist"
		type="revolute">
		<limit effort="1000.0" lower="-3.1" upper="3.1" velocity="0.5"/>
		<origin
			xyz="0 0 0.033268"
			rpy="-6.123E-17 0 0" />
		<parent
			link="base_link" />
		<child
			link="link_1" />
		<axis
			xyz="0 0 -1" />
	</joint>
	<link
		name="link_2">
		<inertial>
			<origin
				xyz="-0.022066 -4.0835E-17 0.067318"
				rpy="0 0 0" />
			<mass
				value="9.0027" />
			<inertia
				ixx="0.034679"
				ixy="-8.5117E-17"
				ixz="-0.009359"
				iyy="0.25195"
				iyz="-2.7279E-18"
				izz="0.26459" />
		</inertial>
		<visual>
			<origin
				xyz="0 0 0"
				rpy="0 0 0" />
			<geometry>
				<mesh
					filename="package://edwin_description/meshes/link_2.STL" />
			</geometry>
			<material
				name="">
				<color
					rgba="0.79216 0.81961 0.93333 1" />
			</material>
		</visual>
		<collision>
			<origin
				xyz="0 0 0"
				rpy="0 0 0" />
			<geometry>
				<mesh
					filename="package://edwin_description/meshes/link_2.STL" />
			</geometry>
		</collision>
	</link>
	<joint
		name="shoulder"
		type="continuous">
		<origin
			xyz="0 0 0.32173"
			rpy="1.5708 1.5708 3.1416" />
		<parent
			link="link_1" />
		<child
			link="link_2" />
		<axis
			xyz="0 0 1" />
	</joint>
	<link
		name="link_3">
		<inertial>
			<origin
				xyz="-0.066663 -0.0021716 -0.055074"
				rpy="0 0 0" />
			<mass
				value="5.6787" />
			<inertia
				ixx="0.010806"
				ixy="-0.0027104"
				ixz="-1.384E-18"
				iyy="0.19386"
				iyz="3.9661E-18"
				izz="0.19319" />
		</inertial>
		<visual>
			<origin
				xyz="0 0 0"
				rpy="0 0 0" />
			<geometry>
				<mesh
					filename="package://edwin_description/meshes/link_3.STL" />
			</geometry>
			<material
				name="">
				<color
					rgba="0.79216 0.81961 0.93333 1" />
			</material>
		</visual>
		<collision>
			<origin
				xyz="0 0 0"
				rpy="0 0 0" />
			<geometry>
				<mesh
					filename="package://edwin_description/meshes/link_3.STL" />
			</geometry>
		</collision>
	</link>
	<joint
		name="elbow"
		type="continuous">
		<origin
			xyz="-0.375 0 0"
			rpy="0 0 -1.1442E-17" />
		<parent
			link="link_2" />
		<child
			link="link_3" />
		<axis
			xyz="0 0 1" />
	</joint>
	<link
		name="link_4">
		<inertial>
			<origin
				xyz="0.00548 2.769E-08 -0.0244"
				rpy="0 0 0" />
			<mass
				value="0.20197" />
			<inertia
				ixx="9.4725E-05"
				ixy="2.5567E-10"
				ixz="1.0595E-21"
				iyy="0.00012085"
				iyz="3.6338E-10"
				izz="0.00013378" />
		</inertial>
		<visual>
			<origin
				xyz="0 0 0"
				rpy="0 0 0" />
			<geometry>
				<mesh
					filename="package://edwin_description/meshes/link_4.STL" />
			</geometry>
			<material
				name="">
				<color
					rgba="0.79216 0.81961 0.93333 1" />
			</material>
		</visual>
		<collision>
			<origin
				xyz="0 0 0"
				rpy="0 0 0" />
			<geometry>
				<mesh
					filename="package://edwin_description/meshes/link_4.STL" />
			</geometry>
		</collision>
	</link>
	<joint
		name="hand"
		type="continuous">
		<origin
			xyz="-0.375 0 0"
			rpy="3.1416 0 3.1416" />
		<parent
			link="link_3" />
		<child
			link="link_4" />
		<axis
			xyz="0 0 -1" />
	</joint>
	<link
		name="link_5">
		<inertial>
			<origin
				xyz="0.079318 1.7347E-17 -0.00054796"
				rpy="0 0 0" />
			<mass
				value="1.1932" />
			<inertia
				ixx="0.002025"
				ixy="8.945E-21"
				ixz="-3.5327E-05"
				iyy="0.0027263"
				iyz="0"
				izz="0.0039407" />
		</inertial>
		<visual>
			<origin
				xyz="0 0 0"
				rpy="0 0 0" />
			<geometry>
				<mesh
					filename="package://edwin_description/meshes/link_5.STL" />
			</geometry>
			<material
				name="">
				<color
					rgba="0.79216 0.81961 0.93333 1" />
			</material>
		</visual>
		<collision>
			<origin
				xyz="0 0 0"
				rpy="0 0 0" />
			<geometry>
				<mesh
					filename="package://edwin_description/meshes/link_5.STL" />
			</geometry>
		</collision>
	</link>
	<joint
		name="wrist"
		type="continuous">
		<origin
			xyz="0.042405 0 -0.0244"
			rpy="-1.9635 6.137E-31 -1.6653E-16" />
		<parent
			link="link_4" />
		<child
			link="link_5" />
		<axis
			xyz="1 0 0" />
	</joint>
	<link
		name="jaw_link">
		<inertial>
			<origin
				xyz="-0.066675 8.6736E-17 -0.0079375"
				rpy="0 0 0" />
			<mass
				value="0.26885" />
			<inertia
				ixx="0.000367"
				ixy="-7.8813E-21"
				ixz="-9.1216E-21"
				iyy="0.00040404"
				iyz="-4.0658E-20"
				izz="0.00075975" />
		</inertial>
		<visual>
			<origin
				xyz="0 0 0"
				rpy="0 0 0" />
			<geometry>
				<mesh
					filename="package://edwin_description/meshes/jaw_link.STL" />
			</geometry>
			<material
				name="">
				<color
					rgba="0.79216 0.81961 0.93333 1" />
			</material>
		</visual>
		<collision>
			<origin
				xyz="0 0 0"
				rpy="0 0 0" />
			<geometry>
				<mesh
					filename="package://edwin_description/meshes/jaw_link.STL" />
			</geometry>
		</collision>
	</link>
	<joint
		name="jaw_joint"
		type="fixed">
		<origin
			xyz="0.15875 0 -0.034925"
			rpy="0 1.2326E-32 2.0251E-16" />
		<parent
			link="link_5" />
		<child
			link="jaw_link" />
		<axis
			xyz="0 1 0" />
	</joint>
	<transmission name="trans_1">
		<type>transmission_interface/SimpleTransmission</type>
		<joint name="waist">
			<hardwareInterface>PositionJointInterface</hardwareInterface>
		</joint>
		<actuator name="motor_1">
			<hardwareInterface>PositionJointInterface</hardwareInterface>
		</actuator>
	</transmission>
	<transmission name="trans_2">
		<type>transmission_interface/SimpleTransmission</type>
		<joint name="shoulder">
			<hardwareInterface>PositionJointInterface</hardwareInterface>
		</joint>
		<actuator name="motor_2">
			<hardwareInterface>PositionJointInterface</hardwareInterface>
		</actuator>
	</transmission>
	<transmission name="trans_3">
		<type>transmission_interface/SimpleTransmission</type>
		<joint name="elbow">
			<hardwareInterface>PositionJointInterface</hardwareInterface>
		</joint>
		<actuator name="motor_3">
			<hardwareInterface>PositionJointInterface</hardwareInterface>
		</actuator>
	</transmission>
	<transmission name="trans_4">
		<type>transmission_interface/SimpleTransmission</type>
		<joint name="hand">
			<hardwareInterface>PositionJointInterface</hardwareInterface>
		</joint>
		<actuator name="motor_4">
			<hardwareInterface>PositionJointInterface</hardwareInterface>
		</actuator>
	</transmission>
	<transmission name="trans_5">
		<type>transmission_interface/SimpleTransmission</type>
		<joint name="wrist">
			<hardwareInterface>PositionJointInterface</hardwareInterface>
		</joint>
		<actuator name="motor_5">
			<hardwareInterface>PositionJointInterface</hardwareInterface>
		</actuator>
	</transmission>

</robot>
