<robot
  name="edwin">
  <link
    name="base_link">
    <inertial>
      <origin
        xyz="-3.7358E-35 -2.529E-18 0.0088139"
        rpy="0 0 0" />
      <mass
        value="1.1856" />
      <inertia
        ixx="0.0059712"
        ixy="4.603E-36"
        ixz="3.0666E-36"
        iyy="0.0059712"
        iyz="-3.325E-19"
        izz="0.011871" />
    </inertial>
    <visual>
      <origin
        xyz="0 0 0"
        rpy="0 0 0" />
      <geometry>
        <mesh
          filename="package://edwin_description/meshes/base_link.STL" />
      </geometry>
      <material
        name="">
        <color
          rgba="0.79216 0.81961 0.93333 1" />
      </material>
    </visual>
    <collision>
      <origin
        xyz="0 0 0"
        rpy="0 0 0" />
      <geometry>
        <mesh
          filename="package://edwin_description/meshes/base_link.STL" />
      </geometry>
    </collision>
  </link>
  <link
    name="link_1">
    <inertial>
      <origin
        xyz="-0.018367 -0.0077664 0.069822"
        rpy="0 0 0" />
      <mass
        value="4.8214" />
      <inertia
        ixx="0.044516"
        ixy="-0.00066637"
        ixz="0.0028019"
        iyy="0.04368"
        iyz="-0.0055911"
        izz="0.03291" />
    </inertial>
    <visual>
      <origin
        xyz="0 0 0"
        rpy="0 0 0" />
      <geometry>
        <mesh
          filename="package://edwin_description/meshes/link_1.STL" />
      </geometry>
      <material
        name="">
        <color
          rgba="0.79216 0.81961 0.93333 1" />
      </material>
    </visual>
    <collision>
      <origin
        xyz="0 0 0"
        rpy="0 0 0" />
      <geometry>
        <mesh
          filename="package://edwin_description/meshes/link_1.STL" />
      </geometry>
    </collision>
  </link>
  <joint
    name="waist"
    type="continuous">
    <origin
      xyz="0 0 0.0332679193608537"
      rpy="-6.12303176911189E-17 0 0" />
    <parent
      link="base_link" />
    <child
      link="link_1" />
    <axis
      xyz="0 0 -1" />
  </joint>
  <link
    name="link_2">
    <inertial>
      <origin
        xyz="-0.022066 -4.0835E-17 0.067318"
        rpy="0 0 0" />
      <mass
        value="9.0027" />
      <inertia
        ixx="0.034679"
        ixy="-8.4905E-17"
        ixz="-0.009359"
        iyy="0.25195"
        iyz="-2.7279E-18"
        izz="0.26459" />
    </inertial>
    <visual>
      <origin
        xyz="0 0 0"
        rpy="0 0 0" />
      <geometry>
        <mesh
          filename="package://edwin_description/meshes/link_2.STL" />
      </geometry>
      <material
        name="">
        <color
          rgba="0.79216 0.81961 0.93333 1" />
      </material>
    </visual>
    <collision>
      <origin
        xyz="0 0 0"
        rpy="0 0 0" />
      <geometry>
        <mesh
          filename="package://edwin_description/meshes/link_2.STL" />
      </geometry>
    </collision>
  </link>
  <joint
    name="shoulder"
    type="continuous">
    <origin
      xyz="0 0 0.32173"
      rpy="1.5708 1.5708 3.1416" />
    <parent
      link="link_1" />
    <child
      link="link_2" />
    <axis
      xyz="0 0 1" />
  </joint>
  <link
    name="link_3">
    <inertial>
      <origin
        xyz="-0.066663 -0.0021716 -0.055074"
        rpy="0 0 0" />
      <mass
        value="5.6787" />
      <inertia
        ixx="0.010806"
        ixy="-0.0027104"
        ixz="-3.0213E-18"
        iyy="0.19386"
        iyz="3.8756E-18"
        izz="0.19319" />
    </inertial>
    <visual>
      <origin
        xyz="0 0 0"
        rpy="0 0 0" />
      <geometry>
        <mesh
          filename="package://edwin_description/meshes/link_3.STL" />
      </geometry>
      <material
        name="">
        <color
          rgba="0.79216 0.81961 0.93333 1" />
      </material>
    </visual>
    <collision>
      <origin
        xyz="0 0 0"
        rpy="0 0 0" />
      <geometry>
        <mesh
          filename="package://edwin_description/meshes/link_3.STL" />
      </geometry>
    </collision>
  </link>
  <joint
    name="elbow"
    type="continuous">
    <origin
      xyz="-0.375 0 0"
      rpy="0 0 -1.1442E-17" />
    <parent
      link="link_2" />
    <child
      link="link_3" />
    <axis
      xyz="0 0 1" />
  </joint>
  <link
    name="link_4">
    <inertial>
      <origin
        xyz="0.00548 2.769E-08 -0.0244"
        rpy="0 0 0" />
      <mass
        value="0.20197" />
      <inertia
        ixx="9.4725E-05"
        ixy="2.5567E-10"
        ixz="3.3235E-21"
        iyy="0.00012085"
        iyz="3.6338E-10"
        izz="0.00013378" />
    </inertial>
    <visual>
      <origin
        xyz="0 0 0"
        rpy="0 0 0" />
      <geometry>
        <mesh
          filename="package://edwin_description/meshes/link_4.STL" />
      </geometry>
      <material
        name="">
        <color
          rgba="0.79216 0.81961 0.93333 1" />
      </material>
    </visual>
    <collision>
      <origin
        xyz="0 0 0"
        rpy="0 0 0" />
      <geometry>
        <mesh
          filename="package://edwin_description/meshes/link_4.STL" />
      </geometry>
    </collision>
  </link>
  <joint
    name="hand"
    type="continuous">
    <origin
      xyz="-0.375 0 0"
      rpy="3.1416 0 3.1416" />
    <parent
      link="link_3" />
    <child
      link="link_4" />
    <axis
      xyz="0 0 -1" />
  </joint>
  <link
    name="link_5">
    <inertial>
      <origin
        xyz="-3.4694E-18 0.0012909 0.055026"
        rpy="0 0 0" />
      <mass
        value="1.0129" />
      <inertia
        ixx="0.0017672"
        ixy="9.4126E-20"
        ixz="-1.4609E-20"
        iyy="0.0017689"
        iyz="3.5992E-05"
        izz="0.0017382" />
    </inertial>
    <visual>
      <origin
        xyz="0 0 0"
        rpy="0 0 0" />
      <geometry>
        <mesh
          filename="package://edwin_description/meshes/link_5.STL" />
      </geometry>
      <material
        name="">
        <color
          rgba="0.79216 0.81961 0.93333 1" />
      </material>
    </visual>
    <collision>
      <origin
        xyz="0 0 0"
        rpy="0 0 0" />
      <geometry>
        <mesh
          filename="package://edwin_description/meshes/link_5.STL" />
      </geometry>
    </collision>
  </link>
  <joint
    name="wrist"
    type="continuous">
    <origin
      xyz="0.042405 0 -0.0244"
      rpy="0 -1.5708 0" />
    <parent
      link="link_4" />
    <child
      link="link_5" />
    <axis
      xyz="0 0 -1" />
  </joint>

  <transmission name="trans_1">
	  <type>transmission_interface/SimpleTransmission</type>
	  <joint name="waist">
		  <hardwareInterface>PositionJointInterface</hardwareInterface>
	  </joint>
	  <actuator name="motor_1">
		  <hardwareInterface>PositionJointInterface</hardwareInterface>
	  </actuator>
  </transmission>
  <transmission name="trans_2">
	  <type>transmission_interface/SimpleTransmission</type>
	  <joint name="shoulder">
		  <hardwareInterface>PositionJointInterface</hardwareInterface>
	  </joint>
	  <actuator name="motor_2">
		  <hardwareInterface>PositionJointInterface</hardwareInterface>
	  </actuator>
  </transmission>
  <transmission name="trans_3">
	  <type>transmission_interface/SimpleTransmission</type>
	  <joint name="elbow">
		  <hardwareInterface>PositionJointInterface</hardwareInterface>
	  </joint>
	  <actuator name="motor_3">
		  <hardwareInterface>PositionJointInterface</hardwareInterface>
	  </actuator>
  </transmission>
  <transmission name="trans_4">
	  <type>transmission_interface/SimpleTransmission</type>
	  <joint name="hand">
		  <hardwareInterface>PositionJointInterface</hardwareInterface>
	  </joint>
	  <actuator name="motor_4">
		  <hardwareInterface>PositionJointInterface</hardwareInterface>
	  </actuator>
  </transmission>
  <transmission name="trans_5">
	  <type>transmission_interface/SimpleTransmission</type>
	  <joint name="wrist">
		  <hardwareInterface>PositionJointInterface</hardwareInterface>
	  </joint>
	  <actuator name="motor_5">
		  <hardwareInterface>PositionJointInterface</hardwareInterface>
	  </actuator>
  </transmission>
</robot>
